Workbook

Sheet Week-by-Week Plan
A1: Renovation Project Spend Tracker (Fill As You Go)
A2: Project Address: | B2: 46 Glenferrie Road, St Albans, AL1 4JU
A3: Assumptions: | B3: Fill in the details as you go: Task/Description, Category, Trade, supplier + receipt details, then enter hours/qty and unit costs. Totals update automatically. Edit labour rates in Lookups.
A5: Week # | B5: Task / Description | C5: Category | D5: Trade | E5: Location/Room | F5: Dependencies/Notes | G5: Supplier | H5: Invoice/Receipt Ref | I5: Paid Date | J5: Payment Method | K5: Hours (Labour) | L5: Rate (£/hr) | M5: Labour Cost (£) | N5: Qty (Materials) | O5: Unit Cost (£) | P5: Materials Cost (£) | Q5: VAT | R5: Total incl. VAT (£) | S5: Status
A6: Week 1
A7: 1 | B7: Labourers | C7: Labour | D7: General Builder | F7: Clearence - 6 man days | I7: Friday 27/2 | J7: Cash | L7: {=_xlfn.IFERROR(VLOOKUP(D7,'Lookups'!$A$2:$C$17,2,FALSE),0)} -> 45 | M7: 450 | P7: {=N7*O7} -> 0 | Q7: 0 | R7: {=(M7+P7)*(1+VALUE(SUBSTITUTE(Q7,"%",""))/100)} -> 450 | S7: Planned
A8: 1 | B8: DMC - Dave | C8: Labour | D8: General Builder | F8: Dave first day on site | I8: Friday 27/2 | J8: Cash | L8: {=_xlfn.IFERROR(VLOOKUP(D8,'Lookups'!$A$2:$C$17,2,FALSE),0)} -> 45 | M8: 220 | P8: {=N8*O8} -> 0 | Q8: 0 | R8: {=(M8+P8)*(1+VALUE(SUBSTITUTE(Q8,"%",""))/100)} -> 220 | S8: Planned
A9: 1 | B9: Adam - Clearance | C9: Labour | D9: Skip/Disposal | F9: Rubbish Removal | I9: Friday 27/2 | J9: Cash | L9: {=_xlfn.IFERROR(VLOOKUP(D9,'Lookups'!$A$2:$C$17,2,FALSE),0)} -> 0 | M9: 1100 | P9: {=N9*O9} -> 0 | Q9: 0 | R9: {=(M9+P9)*(1+VALUE(SUBSTITUTE(Q9,"%",""))/100)} -> 1100 | S9: Planned
A10: 1 | L10: {=_xlfn.IFERROR(VLOOKUP(D10,'Lookups'!$A$2:$C$17,2,FALSE),0)} -> 0 | M10: {=K10*L10} -> 0 | P10: {=N10*O10} -> 0 | Q10: 20% | R10: {=(M10+P10)*(1+VALUE(SUBSTITUTE(Q10,"%",""))/100)} -> 0 | S10: Planned
A11: 1 | L11: {=_xlfn.IFERROR(VLOOKUP(D11,'Lookups'!$A$2:$C$17,2,FALSE),0)} -> 0 | M11: {=K11*L11} -> 0 | P11: {=N11*O11} -> 0 | Q11: 20% | R11: {=(M11+P11)*(1+VALUE(SUBSTITUTE(Q11,"%",""))/100)} -> 0 | S11: Planned
A12: 1 | L12: {=_xlfn.IFERROR(VLOOKUP(D12,'Lookups'!$A$2:$C$17,2,FALSE),0)} -> 0 | M12: {=K12*L12} -> 0 | P12: {=N12*O12} -> 0 | Q12: 20% | R12: {=(M12+P12)*(1+VALUE(SUBSTITUTE(Q12,"%",""))/100)} -> 0 | S12: Planned
A13: 1 | L13: {=_xlfn.IFERROR(VLOOKUP(D13,'Lookups'!$A$2:$C$17,2,FALSE),0)} -> 0 | M13: {=K13*L13} -> 0 | P13: {=N13*O13} -> 0 | Q13: 20% | R13: {=(M13+P13)*(1+VALUE(SUBSTITUTE(Q13,"%",""))/100)} -> 0 | S13: Planned
A14: 1 | L14: {=_xlfn.IFERROR(VLOOKUP(D14,'Lookups'!$A$2:$C$17,2,FALSE),0)} -> 0 | M14: {=K14*L14} -> 0 | P14: {=N14*O14} -> 0 | Q14: 20% | R14: {=(M14+P14)*(1+VALUE(SUBSTITUTE(Q14,"%",""))/100)} -> 0 | S14: Planned
A15: 1 | L15: {=_xlfn.IFERROR(VLOOKUP(D15,'Lookups'!$A$2:$C$17,2,FALSE),0)} -> 0 | M15: {=K15*L15} -> 0 | P15: {=N15*O15} -> 0 | Q15: 20% | R15: {=(M15+P15)*(1+VALUE(SUBSTITUTE(Q15,"%",""))/100)} -> 0 | S15: Planned
A16: 1 | L16: {=_xlfn.IFERROR(VLOOKUP(D16,'Lookups'!$A$2:$C$17,2,FALSE),0)} -> 0 | M16: {=K16*L16} -> 0 | P16: {=N16*O16} -> 0 | Q16: 20% | R16: {=(M16+P16)*(1+VALUE(SUBSTITUTE(Q16,"%",""))/100)} -> 0 | S16: Planned
A17: 1 | L17: {=_xlfn.IFERROR(VLOOKUP(D17,'Lookups'!$A$2:$C$17,2,FALSE),0)} -> 0 | M17: {=K17*L17} -> 0 | P17: {=N17*O17} -> 0 | Q17: 20% | R17: {=(M17+P17)*(1+VALUE(SUBSTITUTE(Q17,"%",""))/100)} -> 0 | S17: Planned
A18: 1 | L18: {=_xlfn.IFERROR(VLOOKUP(D18,'Lookups'!$A$2:$C$17,2,FALSE),0)} -> 0 | M18: {=K18*L18} -> 0 | P18: {=N18*O18} -> 0 | Q18: 20% | R18: {=(M18+P18)*(1+VALUE(SUBSTITUTE(Q18,"%",""))/100)} -> 0 | S18: Planned
A19: Week 2
A20: 2 | B20: Labourers | C20: Labour | D20: General Builder | F20: Clearence / back to brick - 9 d | I20: Friday 6/3 | J20: Cash | L20: {=_xlfn.IFERROR(VLOOKUP(D20,'Lookups'!$A$2:$C$17,2,FALSE),0)} -> 45 | M20: 675 | P20: {=N20*O20} -> 0 | Q20: 0 | R20: {=(M20+P20)*(1+VALUE(SUBSTITUTE(Q20,"%",""))/100)} -> 675 | S20: Planned
A21: 2 | B21: Adam - Clearance | C21: Labour | D21: Skip/Disposal | F21: Rubbish Removal | I21: Friday 6/3 | J21: Cash | L21: {=_xlfn.IFERROR(VLOOKUP(D21,'Lookups'!$A$2:$C$17,2,FALSE),0)} -> 0 | M21: 1000 | P21: {=N21*O21} -> 0 | Q21: 0 | R21: {=(M21+P21)*(1+VALUE(SUBSTITUTE(Q21,"%",""))/100)} -> 1000 | S21: Planned
A22: 2 | L22: {=_xlfn.IFERROR(VLOOKUP(D22,'Lookups'!$A$2:$C$17,2,FALSE),0)} -> 0 | M22: {=K22*L22} -> 0 | P22: {=N22*O22} -> 0 | Q22: 20% | R22: {=(M22+P22)*(1+VALUE(SUBSTITUTE(Q22,"%",""))/100)} -> 0 | S22: Planned
A23: 2 | L23: {=_xlfn.IFERROR(VLOOKUP(D23,'Lookups'!$A$2:$C$17,2,FALSE),0)} -> 0 | M23: {=K23*L23} -> 0 | P23: {=N23*O23} -> 0 | Q23: 20% | R23: {=(M23+P23)*(1+VALUE(SUBSTITUTE(Q23,"%",""))/100)} -> 0 | S23: Planned
A24: 2 | L24: {=_xlfn.IFERROR(VLOOKUP(D24,'Lookups'!$A$2:$C$17,2,FALSE),0)} -> 0 | M24: {=K24*L24} -> 0 | P24: {=N24*O24} -> 0 | Q24: 20% | R24: {=(M24+P24)*(1+VALUE(SUBSTITUTE(Q24,"%",""))/100)} -> 0 | S24: Planned
A25: 2 | L25: {=_xlfn.IFERROR(VLOOKUP(D25,'Lookups'!$A$2:$C$17,2,FALSE),0)} -> 0 | M25: {=K25*L25} -> 0 | P25: {=N25*O25} -> 0 | Q25: 20% | R25: {=(M25+P25)*(1+VALUE(SUBSTITUTE(Q25,"%",""))/100)} -> 0 | S25: Planned
A26: 2 | L26: {=_xlfn.IFERROR(VLOOKUP(D26,'Lookups'!$A$2:$C$17,2,FALSE),0)} -> 0 | M26: {=K26*L26} -> 0 | P26: {=N26*O26} -> 0 | Q26: 20% | R26: {=(M26+P26)*(1+VALUE(SUBSTITUTE(Q26,"%",""))/100)} -> 0 | S26: Planned
A27: 2 | L27: {=_xlfn.IFERROR(VLOOKUP(D27,'Lookups'!$A$2:$C$17,2,FALSE),0)} -> 0 | M27: {=K27*L27} -> 0 | P27: {=N27*O27} -> 0 | Q27: 20% | R27: {=(M27+P27)*(1+VALUE(SUBSTITUTE(Q27,"%",""))/100)} -> 0 | S27: Planned
A28: 2 | L28: {=_xlfn.IFERROR(VLOOKUP(D28,'Lookups'!$A$2:$C$17,2,FALSE),0)} -> 0 | M28: {=K28*L28} -> 0 | P28: {=N28*O28} -> 0 | Q28: 20% | R28: {=(M28+P28)*(1+VALUE(SUBSTITUTE(Q28,"%",""))/100)} -> 0 | S28: Planned
A29: 2 | L29: {=_xlfn.IFERROR(VLOOKUP(D29,'Lookups'!$A$2:$C$17,2,FALSE),0)} -> 0 | M29: {=K29*L29} -> 0 | P29: {=N29*O29} -> 0 | Q29: 20% | R29: {=(M29+P29)*(1+VALUE(SUBSTITUTE(Q29,"%",""))/100)} -> 0 | S29: Planned
A30: 2 | L30: {=_xlfn.IFERROR(VLOOKUP(D30,'Lookups'!$A$2:$C$17,2,FALSE),0)} -> 0 | M30: {=K30*L30} -> 0 | P30: {=N30*O30} -> 0 | Q30: 20% | R30: {=(M30+P30)*(1+VALUE(SUBSTITUTE(Q30,"%",""))/100)} -> 0 | S30: Planned
A31: 2 | L31: {=_xlfn.IFERROR(VLOOKUP(D31,'Lookups'!$A$2:$C$17,2,FALSE),0)} -> 0 | M31: {=K31*L31} -> 0 | P31: {=N31*O31} -> 0 | Q31: 20% | R31: {=(M31+P31)*(1+VALUE(SUBSTITUTE(Q31,"%",""))/100)} -> 0 | S31: Planned
A32: Week 3
A33: 3 | B33: Labourers | C33: Labour | D33: General Builder | F33: Clearence / back to brick - 7 d | I33: Friday 13/3 | J33: Cash | L33: {=_xlfn.IFERROR(VLOOKUP(D33,'Lookups'!$A$2:$C$17,2,FALSE),0)} -> 45 | M33: 525 | P33: {=N33*O33} -> 0 | Q33: 0 | R33: {=(M33+P33)*(1+VALUE(SUBSTITUTE(Q33,"%",""))/100)} -> 525 | S33: Planned
A34: 3 | L34: {=_xlfn.IFERROR(VLOOKUP(D34,'Lookups'!$A$2:$C$17,2,FALSE),0)} -> 0 | M34: {=K34*L34} -> 0 | P34: {=N34*O34} -> 0 | Q34: 20% | R34: {=(M34+P34)*(1+VALUE(SUBSTITUTE(Q34,"%",""))/100)} -> 0 | S34: Planned
A35: 3 | L35: {=_xlfn.IFERROR(VLOOKUP(D35,'Lookups'!$A$2:$C$17,2,FALSE),0)} -> 0 | M35: {=K35*L35} -> 0 | P35: {=N35*O35} -> 0 | Q35: 20% | R35: {=(M35+P35)*(1+VALUE(SUBSTITUTE(Q35,"%",""))/100)} -> 0 | S35: Planned
A36: 3 | L36: {=_xlfn.IFERROR(VLOOKUP(D36,'Lookups'!$A$2:$C$17,2,FALSE),0)} -> 0 | M36: {=K36*L36} -> 0 | P36: {=N36*O36} -> 0 | Q36: 20% | R36: {=(M36+P36)*(1+VALUE(SUBSTITUTE(Q36,"%",""))/100)} -> 0 | S36: Planned
A37: 3 | L37: {=_xlfn.IFERROR(VLOOKUP(D37,'Lookups'!$A$2:$C$17,2,FALSE),0)} -> 0 | M37: {=K37*L37} -> 0 | P37: {=N37*O37} -> 0 | Q37: 20% | R37: {=(M37+P37)*(1+VALUE(SUBSTITUTE(Q37,"%",""))/100)} -> 0 | S37: Planned
A38: 3 | L38: {=_xlfn.IFERROR(VLOOKUP(D38,'Lookups'!$A$2:$C$17,2,FALSE),0)} -> 0 | M38: {=K38*L38} -> 0 | P38: {=N38*O38} -> 0 | Q38: 0% | R38: {=(M38+P38)*(1+VALUE(SUBSTITUTE(Q38,"%",""))/100)} -> 0 | S38: Planned
A39: 3 | L39: {=_xlfn.IFERROR(VLOOKUP(D39,'Lookups'!$A$2:$C$17,2,FALSE),0)} -> 0 | M39: {=K39*L39} -> 0 | P39: {=N39*O39} -> 0 | Q39: 20% | R39: {=(M39+P39)*(1+VALUE(SUBSTITUTE(Q39,"%",""))/100)} -> 0 | S39: Planned
A40: 3 | L40: {=_xlfn.IFERROR(VLOOKUP(D40,'Lookups'!$A$2:$C$17,2,FALSE),0)} -> 0 | M40: {=K40*L40} -> 0 | P40: {=N40*O40} -> 0 | Q40: 20% | R40: {=(M40+P40)*(1+VALUE(SUBSTITUTE(Q40,"%",""))/100)} -> 0 | S40: Planned
A41: 3 | L41: {=_xlfn.IFERROR(VLOOKUP(D41,'Lookups'!$A$2:$C$17,2,FALSE),0)} -> 0 | M41: {=K41*L41} -> 0 | P41: {=N41*O41} -> 0 | Q41: 20% | R41: {=(M41+P41)*(1+VALUE(SUBSTITUTE(Q41,"%",""))/100)} -> 0 | S41: Planned
...

Sheet Summary
A1: Project Summary
A2: Project Address: | B2: 46 Glenferrie Road, St Albans, AL1 4JU
A4: By Week (Totals)
A5: Week # | B5: Labour (£) | C5: Materials (£) | D5: Total incl. VAT (£) | E5: Completion % (manual)
A6: 1 | B6: {=SUMIF('Week-by-Week Plan'!$A$6:$A$293,A6,'Week-by-Week Plan'!$M$6:$M$293)} -> 1770 | C6: {=SUMIF('Week-by-Week Plan'!$A$6:$A$293,A6,'Week-by-Week Plan'!$P$6:$P$293)} -> 0 | D6: {=SUMIF('Week-by-Week Plan'!$A$6:$A$293,A6,'Week-by-Week Plan'!$R$6:$R$293)} -> 1770
A7: 2 | B7: {=SUMIF('Week-by-Week Plan'!$A$6:$A$293,A7,'Week-by-Week Plan'!$M$6:$M$293)} -> 1675 | C7: {=SUMIF('Week-by-Week Plan'!$A$6:$A$293,A7,'Week-by-Week Plan'!$P$6:$P$293)} -> 0 | D7: {=SUMIF('Week-by-Week Plan'!$A$6:$A$293,A7,'Week-by-Week Plan'!$R$6:$R$293)} -> 1675
A8: 3 | B8: {=SUMIF('Week-by-Week Plan'!$A$6:$A$293,A8,'Week-by-Week Plan'!$M$6:$M$293)} -> 525 | C8: {=SUMIF('Week-by-Week Plan'!$A$6:$A$293,A8,'Week-by-Week Plan'!$P$6:$P$293)} -> 0 | D8: {=SUMIF('Week-by-Week Plan'!$A$6:$A$293,A8,'Week-by-Week Plan'!$R$6:$R$293)} -> 525
A9: 4 | B9: {=SUMIF('Week-by-Week Plan'!$A$6:$A$293,A9,'Week-by-Week Plan'!$M$6:$M$293)} -> 1550 | C9: {=SUMIF('Week-by-Week Plan'!$A$6:$A$293,A9,'Week-by-Week Plan'!$P$6:$P$293)} -> 0 | D9: {=SUMIF('Week-by-Week Plan'!$A$6:$A$293,A9,'Week-by-Week Plan'!$R$6:$R$293)} -> 1550
A10: 5 | B10: {=SUMIF('Week-by-Week Plan'!$A$6:$A$293,A10,'Week-by-Week Plan'!$M$6:$M$293)} -> 3205 | C10: {=SUMIF('Week-by-Week Plan'!$A$6:$A$293,A10,'Week-by-Week Plan'!$P$6:$P$293)} -> 0 | D10: {=SUMIF('Week-by-Week Plan'!$A$6:$A$293,A10,'Week-by-Week Plan'!$R$6:$R$293)} -> 3205
A11: 6 | B11: {=SUMIF('Week-by-Week Plan'!$A$6:$A$293,A11,'Week-by-Week Plan'!$M$6:$M$293)} -> 2500 | C11: {=SUMIF('Week-by-Week Plan'!$A$6:$A$293,A11,'Week-by-Week Plan'!$P$6:$P$293)} -> 0 | D11: {=SUMIF('Week-by-Week Plan'!$A$6:$A$293,A11,'Week-by-Week Plan'!$R$6:$R$293)} -> 2500
A12: 7 | B12: {=SUMIF('Week-by-Week Plan'!$A$6:$A$293,A12,'Week-by-Week Plan'!$M$6:$M$293)} -> 1050 | C12: {=SUMIF('Week-by-Week Plan'!$A$6:$A$293,A12,'Week-by-Week Plan'!$P$6:$P$293)} -> 0 | D12: {=SUMIF('Week-by-Week Plan'!$A$6:$A$293,A12,'Week-by-Week Plan'!$R$6:$R$293)} -> 2048.4
A13: 8 | B13: {=SUMIF('Week-by-Week Plan'!$A$6:$A$293,A13,'Week-by-Week Plan'!$M$6:$M$293)} -> 2425 | C13: {=SUMIF('Week-by-Week Plan'!$A$6:$A$293,A13,'Week-by-Week Plan'!$P$6:$P$293)} -> 0 | D13: {=SUMIF('Week-by-Week Plan'!$A$6:$A$293,A13,'Week-by-Week Plan'!$R$6:$R$293)} -> 2425
A14: 9 | B14: {=SUMIF('Week-by-Week Plan'!$A$6:$A$293,A14,'Week-by-Week Plan'!$M$6:$M$293)} -> 6110 | C14: {=SUMIF('Week-by-Week Plan'!$A$6:$A$293,A14,'Week-by-Week Plan'!$P$6:$P$293)} -> 0 | D14: 6110
A15: 10 | B15: {=SUMIF('Week-by-Week Plan'!$A$6:$A$293,A15,'Week-by-Week Plan'!$M$6:$M$293)} -> 2915 | C15: {=SUMIF('Week-by-Week Plan'!$A$6:$A$293,A15,'Week-by-Week Plan'!$P$6:$P$293)} -> 0 | D15: 2915
A16: 11 | B16: {=SUMIF('Week-by-Week Plan'!$A$6:$A$293,A16,'Week-by-Week Plan'!$M$6:$M$293)} -> 700 | C16: {=SUMIF('Week-by-Week Plan'!$A$6:$A$293,A16,'Week-by-Week Plan'!$P$6:$P$293)} -> 0 | D16: 700
A17: 12 | B17: {=SUMIF('Week-by-Week Plan'!$A$6:$A$293,A17,'Week-by-Week Plan'!$M$6:$M$293)} -> 4000 | C17: {=SUMIF('Week-by-Week Plan'!$A$6:$A$293,A17,'Week-by-Week Plan'!$P$6:$P$293)} -> 0 | D17: 4000
A18: 13 | B18: {=SUMIF('Week-by-Week Plan'!$A$6:$A$293,A18,'Week-by-Week Plan'!$M$6:$M$293)} -> 2575 | C18: {=SUMIF('Week-by-Week Plan'!$A$6:$A$293,A18,'Week-by-Week Plan'!$P$6:$P$293)} -> 0 | D18: 2575
A19: 14 | B19: {=SUMIF('Week-by-Week Plan'!$A$6:$A$293,A19,'Week-by-Week Plan'!$M$6:$M$293)} -> 2520 | C19: {=SUMIF('Week-by-Week Plan'!$A$6:$A$293,A19,'Week-by-Week Plan'!$P$6:$P$293)} -> 0 | D19: {=SUMIF('Week-by-Week Plan'!$A$6:$A$293,A19,'Week-by-Week Plan'!$R$6:$R$293)} -> 2520
A20: 15 | B20: {=SUMIF('Week-by-Week Plan'!$A$6:$A$293,A20,'Week-by-Week Plan'!$M$6:$M$293)} -> 6997.84 | C20: {=SUMIF('Week-by-Week Plan'!$A$6:$A$293,A20,'Week-by-Week Plan'!$P$6:$P$293)} -> 0 | D20: {=SUMIF('Week-by-Week Plan'!$A$6:$A$293,A20,'Week-by-Week Plan'!$R$6:$R$293)} -> 7893.408
A21: 16 | B21: {=SUMIF('Week-by-Week Plan'!$A$6:$A$293,A21,'Week-by-Week Plan'!$M$6:$M$293)} -> 0 | C21: {=SUMIF('Week-by-Week Plan'!$A$6:$A$293,A21,'Week-by-Week Plan'!$P$6:$P$293)} -> 0 | D21: {=SUMIF('Week-by-Week Plan'!$A$6:$A$293,A21,'Week-by-Week Plan'!$R$6:$R$293)} -> 0
A22: 17 | B22: {=SUMIF('Week-by-Week Plan'!$A$6:$A$293,A22,'Week-by-Week Plan'!$M$6:$M$293)} -> 0 | C22: {=SUMIF('Week-by-Week Plan'!$A$6:$A$293,A22,'Week-by-Week Plan'!$P$6:$P$293)} -> 0 | D22: {=SUMIF('Week-by-Week Plan'!$A$6:$A$293,A22,'Week-by-Week Plan'!$R$6:$R$293)} -> 0
A23: 18 | B23: {=SUMIF('Week-by-Week Plan'!$A$6:$A$293,A23,'Week-by-Week Plan'!$M$6:$M$293)} -> 0 | C23: {=SUMIF('Week-by-Week Plan'!$A$6:$A$293,A23,'Week-by-Week Plan'!$P$6:$P$293)} -> 0 | D23: {=SUMIF('Week-by-Week Plan'!$A$6:$A$293,A23,'Week-by-Week Plan'!$R$6:$R$293)} -> 0
A24: 19 | B24: {=SUMIF('Week-by-Week Plan'!$A$6:$A$293,A24,'Week-by-Week Plan'!$M$6:$M$293)} -> 0 | C24: {=SUMIF('Week-by-Week Plan'!$A$6:$A$293,A24,'Week-by-Week Plan'!$P$6:$P$293)} -> 0 | D24: {=SUMIF('Week-by-Week Plan'!$A$6:$A$293,A24,'Week-by-Week Plan'!$R$6:$R$293)} -> 0
A25: 20 | B25: {=SUMIF('Week-by-Week Plan'!$A$6:$A$293,A25,'Week-by-Week Plan'!$M$6:$M$293)} -> 0 | C25: {=SUMIF('Week-by-Week Plan'!$A$6:$A$293,A25,'Week-by-Week Plan'!$P$6:$P$293)} -> 0 | D25: {=SUMIF('Week-by-Week Plan'!$A$6:$A$293,A25,'Week-by-Week Plan'!$R$6:$R$293)} -> 0
A26: 21 | B26: {=SUMIF('Week-by-Week Plan'!$A$6:$A$293,A26,'Week-by-Week Plan'!$M$6:$M$293)} -> 0 | C26: {=SUMIF('Week-by-Week Plan'!$A$6:$A$293,A26,'Week-by-Week Plan'!$P$6:$P$293)} -> 0 | D26: {=SUMIF('Week-by-Week Plan'!$A$6:$A$293,A26,'Week-by-Week Plan'!$R$6:$R$293)} -> 0
A27: 22 | B27: {=SUMIF('Week-by-Week Plan'!$A$6:$A$293,A27,'Week-by-Week Plan'!$M$6:$M$293)} -> 0 | C27: {=SUMIF('Week-by-Week Plan'!$A$6:$A$293,A27,'Week-by-Week Plan'!$P$6:$P$293)} -> 0 | D27: {=SUMIF('Week-by-Week Plan'!$A$6:$A$293,A27,'Week-by-Week Plan'!$R$6:$R$293)} -> 0
A29: Controls
A30: Target Budget (incl. VAT) | B30: 0
A31: Forecast Total (incl. VAT) | B31: {=SUM(D6:D27)} -> 42411.808
A32: Variance (Forecast - Budget) | B32: {=B31-B30} -> 42411.808
A33: Contingency % | B33: 0
A34: Contingency Amount | B34: {=B31*B33/100} -> 0
A35: Forecast + Contingency | B35: {=B31+B34} -> 42411.808
A38: How to use:
A39: 1) In 'Week-by-Week Plan', update each task with accurate hours/quantities and unit costs. 2) Choose Category, Trade, VAT and Status from dropdowns. 3) 'Summary' auto-aggregates totals by week and overall forecast. Tip: Duplicate/insert new rows as needed; keep formulas consistent.

Sheet Lookups
A1: Trade | B1: Default Labour Rate (£/hr) | C1: Default Markup %
A2: General Builder | B2: 45 | C2: 10
A3: Carpenter/Joiner | B3: 50 | C3: 10
A4: Plumber | B4: 60 | C4: 10
A5: Electrician | B5: 65 | C5: 10
A6: Plasterer | B6: 55 | C6: 10
A7: Tiler | B7: 55 | C7: 10
A8: Decorator | B8: 45 | C8: 10
A9: Roofer | B9: 60 | C9: 10
A10: Groundworker | B10: 55 | C10: 10
A11: Kitchen Fitter | B11: 55 | C11: 10
A12: Bathroom Fitter | B12: 55 | C12: 10
A13: Glazier | B13: 55 | C13: 10
... A17: Other | B17: 50 | C17: 10
