Workbook

Sheet Dashboard
A1: Category | B1: Quoted (£) | C1: Actual (£) | D1: Paid (£) | E1: Remaining (£) | F1: Status
A2: Trades & Labour | B2: {=SUM('Trades & Labour'!C2:C100)} -> 25430 | C2: {=SUM('Trades & Labour'!D2:D100)} -> 25430 | D2: {=SUM('Trades & Labour'!E2:E100)} -> 25430 | E2: {=C2-D2} -> 0 | F2: {=IF(D2<=C2,"✅ On Budget","⚠️ Over Budget")} -> ✅ On Budget
A3: Materials & Suppliers | B3: {=SUM('Materials & Suppliers'!F2:F99)} -> 73502.12 | C3: {=SUM('Materials & Suppliers'!G2:G99)} -> 73502.12 | D3: {=SUM('Materials & Suppliers'!G2:G99)} -> 73502.12 | E3: {=C3-D3} -> 0 | F3: {=IF(D3<=C3,"✅ On Budget","⚠️ Over Budget")} -> ✅ On Budget

Sheet Trades & Labour
A1: Trade | B1: Supplier / Name | C1: Quoted (£) | D1: Actual (£) | E1: Paid (£) | F1: Date Paid | G1: Remaining (£) | H1: Status | I1: Notes
B2: Vince | C2: 440 | D2: 440 | E2: 440 | F2: 45978 | H2: {=IF(D2<=C2,"✅ On Budget","⚠️ Over Budget")} -> ✅ On Budget | I2: 2 days
B3: Venkat | C3: 525 | D3: 525 | E3: 525 | F3: 45978 | H3: {=IF(D3<=C3,"✅ On Budget","⚠️ Over Budget")} -> ✅ On Budget | I3: 6 days
B4: Dave Gardener | C4: 1350 | D4: 1350 | E4: 1350 | F4: 45978 | G4: {=C4-D4} -> 0 | H4: {=IF(D4<=C4,"✅ On Budget","⚠️ Over Budget")} -> ✅ On Budget
B5: James Chippy | C5: 510 | D5: 510 | E5: 510 | F5: 45974 | G5: {=C5-D5} -> 0 | H5: {=IF(D5<=C5,"✅ On Budget","⚠️ Over Budget")} -> ✅ On Budget | I5: 2 days plus fixings
B6: Vince | C6: 1100 | D6: 1100 | E6: 1100 | F6: 45975 | G6: {=C6-D6} -> 0 | H6: {=IF(D6<=C6,"✅ On Budget","⚠️ Over Budget")} -> ✅ On Budget | I6: 5 days - £540 towards Mac | J6: £540 max
B7: Venkat | C7: 375 | D7: 375 | E7: 375 | F7: 45975 | G7: {=C7-D7} -> 0 | H7: {=IF(D7<=C7,"✅ On Budget","⚠️ Over Budget")} -> ✅ On Budget | I7: 5 days
B8: James Chippy | C8: 270 | D8: 270 | E8: 270 | F8: 45981 | G8: {=C8-D8} -> 0 | H8: {=IF(D8<=C8,"✅ On Budget","⚠️ Over Budget")} -> ✅ On Budget | I8: 1 day plus materials
B9: Dave Gardener | C9: 2250 | D9: 2250 | E9: 2250 | F9: 45982 | G9: {=C9-D9} -> 0 | H9: {=IF(D9<=C9,"✅ On Budget","⚠️ Over Budget")} -> ✅ On Budget | I9: 5 days labour
B10: Venky | C10: 540 | D10: 540 | E10: 540 | F10: 45982 | G10: {=C10-D10} -> 0 | H10: {=IF(D10<=C10,"✅ On Budget","⚠️ Over Budget")} -> ✅ On Budget | I10: 4 days Venky, 1 day AJ, Anil, Barat
B11: Vince + Simon | C11: 440 | D11: 440 | E11: 440 | F11: 45982 | G11: {=C11-D11} -> 0 | H11: {=IF(D11<=C11,"✅ On Budget","⚠️ Over Budget")} -> ✅ On Budget | I11: 2 days for UFH + Chippy studs in bathrooms (£480 to mac) | J11: £480 to mac
B12: Dave Gardener | C12: 1350 | D12: 1350 | E12: 1350 | F12: 45989 | G12: {=C12-D12} -> 0 | H12: {=IF(D12<=C12,"✅ On Budget","⚠️ Over Budget")} -> ✅ On Budget | I12: 3 days to finish back garden inc slabbing all around 100m2
B13: Dave / Simon | C13: 1100 | D13: 1100 | E13: 1100 | F13: 45989 | G13: {=C13-D13} -> 0 | H13: {=IF(D13<=C13,"✅ On Budget","⚠️ Over Budget")} -> ✅ On Budget | I13: 5 days - gutters / fascias entire week (! Day on fixing window area) | J13: £300 mac
B14: Martin Plasterer | C14: 1000 | D14: 1000 | E14: 1000 | F14: 45989 | G14: {=C14-D14} -> 0 | H14: {=IF(D14<=C14,"✅ On Budget","⚠️ Over Budget")} -> ✅ On Budget | I14: 2 days for 3 lads
B15: Venky | C15: 525 | D15: 525 | E15: 525 | F15: 45989 | G15: {=C15-D15} -> 0 | H15: {=IF(D15<=C15,"✅ On Budget","⚠️ Over Budget")} -> ✅ On Budget | I15: 7 man days for labourers….. Turfing... Garden …. Then Thurs Frid helping simon with Fascias
B16: Plasterers | C16: 400 | D16: 400 | E16: 400 | F16: 45990 | G16: {=C16-D16} -> 0 | H16: {=IF(D16<=C16,"✅ On Budget","⚠️ Over Budget")} -> ✅ On Budget | I16: 2 plasterers SAT 29/11
B17: Venky | C17: 150 | D17: 150 | E17: 150 | F17: 45996 | G17: {=C17-D17} -> 0 | H17: {=IF(D17<=C17,"✅ On Budget","⚠️ Over Budget")} -> ✅ On Budget | I17: 2 days labour
B18: Garden | C18: 300 | D18: 300 | E18: 300 | F18: 45996 | G18: {=C18-D18} -> 0 | H18: {=IF(D18<=C18,"✅ On Budget","⚠️ Over Budget")} -> ✅ On Budget | I18: clear 7 tree stumps out front
B19: Roof clean plus repair | C19: 1300 | D19: 1300 | E19: 1300 | F19: 45996 | G19: {=C19-D19} -> 0 | H19: {=IF(D19<=C19,"✅ On Budget","⚠️ Over Budget")} -> ✅ On Budget
B20: dave | C20: 460 | D20: 460 | E20: 460 | F20: 45996 | G20: {=C20-D20} -> 0 | H20: {=IF(D20<=C20,"✅ On Budget","⚠️ Over Budget")} -> ✅ On Budget | I20: 2 days simon plus materials
B21: Tiler | C21: 1500 | D21: 1500 | E21: 1500 | F21: 45996 | G21: {=C21-D21} -> 0 | H21: {=IF(D21<=C21,"✅ On Budget","⚠️ Over Budget")} -> ✅ On Budget | I21: Tiler paid - £2500 remaining
B22: SRI Kitchen fitters | C22: 1600 | D22: 1600 | E22: 1600 | F22: 46003 | G22: {=C22-D22} -> 0 | H22: {=IF(D22<=C22,"✅ On Budget","⚠️ Over Budget")} -> ✅ On Budget | I22: Cash paid
B23: Tiler | C23: 1000 | D23: 1000 | E23: 1000 | F23: 46003 | G23: {=C23-D23} -> 0 | H23: {=IF(D23<=C23,"✅ On Budget","⚠️ Over Budget")} -> ✅ On Budget
B24: Stuart Miscoat | C24: 150 | D24: 150 | E24: 150 | F24: 46003 | G24: {=C24-D24} -> 0 | H24: {=IF(D24<=C24,"✅ On Budget","⚠️ Over Budget")} -> ✅ On Budget | I24: Spray miscoat
B25: Dave / Simon | C25: 1100 | D25: 1100 | E25: 1100 | F25: 46003 | G25: {=C25-D25} -> 0 | H25: {=IF(D25<=C25,"✅ On Budget","⚠️ Over Budget")} -> ✅ On Budget | I25: Paid… £1050…. £50 towards Mac | J25: £50 to Mac
B26: Dave Gardener | C26: 225 | D26: 225 | E26: 225 | F26: 46003 | G26: {=C26-D26} -> 0 | H26: {=IF(D26<=C26,"✅ On Budget","⚠️ Over Budget")} -> ✅ On Budget | I26: 1/2 day …. Dave and co slabbed the front…. 15m2 layed
B27: Mickey - Grout Garden | C27: 150 | D27: 150 | E27: 150 | F27: 46004 | G27: {=C27-D27} -> 0 | H27: {=IF(D27<=C27,"✅ On Budget","⚠️ Over Budget")} -> ✅ On Budget
B28: Tom Chippie | C28: 565 | D28: 565 | E28: 565 | F28: 45975 | G28: {=C28-D28} -> 0 | H28: {=IF(D28<=C28,"✅ On Budget","⚠️ Over Budget")} -> ✅ On Budget | I28: Paid… £30 per hour Tom + £25 / hour for his mate | J28: Did all doors, arch + skirting
B29: Venky | C29: 150 | D29: 150 | E29: 150 | F29: 46006 | G29: {=C29-D29} -> 0 | H29: {=IF(D29<=C29,"✅ On Budget","⚠️ Over Budget")} -> ✅ On Budget | I29: 2.5 days.
B30: Dave Gardener | C30: 300 | D30: 300 | E30: 300 | F30: 46006 | G30: {=C30-D30} -> 0 | H30: {=IF(D30<=C30,"✅ On Budget","⚠️ Over Budget")} -> ✅ On Budget | I30: 1 day dave… finished job
B31: Dan Painter | C31: 650 | D31: 650 | E31: 650 | F31: 46010 | G31: {=C31-D31} -> 0 | H31: {=IF(D31<=C31,"✅ On Budget","⚠️ Over Budget")} -> ✅ On Budget | I31: 3 days Stu @ £160 + 1 day Dan @ £170 | J31: dan paid £170 towards Spray Paint machine
B32: Tiler | C32: 1610 | D32: 1610 | E32: 1610 | F32: 46010 | G32: {=C32-D32} -> 0 | H32: {=IF(D32<=C32,"✅ On Budget","⚠️ Over Budget")} -> ✅ On Budget | I32: remaining tile labour - £200 for extra adhesive
B33: Dan Painter | C33: 550 | D33: 550 | E33: 550 | F33: 46014 | G33: {=C33-D33} -> 0 | H33: {=IF(D33<=C33,"✅ On Budget","⚠️ Over Budget")} -> ✅ On Budget | I33: bank transfer
B34: Dave Chippie | C34: 220 | D34: 220 | E34: 220 | F34: 46031 | G34: {=C34-D34} -> 0 | H34: {=IF(D34<=C34,"✅ On Budget","⚠️ Over Budget")} -> ✅ On Budget | I34: Chippie for bespoke cupboard in utility
B35: Dan Painter | C35: 1075 | D35: 1075 | E35: 1075 | F35: 46031 | G35: {=C35-D35} -> 0 | H35: {=IF(D35<=C35,"✅ On Budget","⚠️ Over Budget")} -> ✅ On Budget | J35: £200 rowards paint sprayer
B36: Dan Painter | C36: 100 | D36: 100 | E36: 100 | F36: 46038 | G36: {=C36-D36} -> 0 | H36: {=IF(D36<=C36,"✅ On Budget","⚠️ Over Budget")} -> ✅ On Budget | J36: £70 to paint sprayer
B37: Venkat | C37: 100 | D37: 100 | E37: 100 | F37: 46038 | G37: {=C37-D37} -> 0 | H37: {=IF(D37<=C37,"✅ On Budget","⚠️ Over Budget")} -> ✅ On Budget | I37: final clean up, soffit paints etc
G38: {=C38-D38} -> 0 | H38: {=IF(D38<=C38,"✅ On Budget","⚠️ Over Budget")} -> ✅ On Budget
G39: {=C39-D39} -> 0 | H39: {=IF(D39<=C39,"✅ On Budget","⚠️ Over Budget")} -> ✅ On Budget
G40: {=C40-D40} -> 0 | H40: {=IF(D40<=C40,"✅ On Budget","⚠️ Over Budget")} -> ✅ On Budget
...

Sheet Materials & Suppliers
A1: Category | B1: Item | C1: Supplier | D1: Unit Cost (£) | E1: Quantity | F1: Total (£) | G1: Paid (£) | H1: Date Paid | I1: Notes
C2: Alspec Windows | D2: 5000 | E2: 1 | F2: {=D2*E2} -> 5000 | G2: 5000 | H2: 45963 | I2: Bank T Walkern
C3: Stevenage Skips | D3: 390 | E3: 1 | F3: {=D3*E3} -> 390 | G3: 390 | H3: 45965 | I3: Cash payment
C4: Wunda UFH | D4: 416.05 | E4: 1 | F4: {=D4*E4} -> 416.05 | G4: 416.05 | H4: 45964 | I4: Bank T Walkern - Deposit paid 90% remaining
C5: Wunda UFH | D5: 3586 | E5: 1 | F5: {=D5*E5} -> 3586 | G5: 3586 | H5: 45966 | I5: Wunda UFH - Bank T
C6: Kitchen- Cabinets Direct | D6: 6000 | E6: 1 | F6: {=D6*E6} -> 6000 | G6: 6000 | H6: 45968 | I6: Paid Cash - £2500 remaining
C7: Lawsons | D7: 336.78 | E7: 1 | F7: {=D7*E7} -> 336.78 | G7: 336.78 | H7: 45971 | I7: Paid Mama | J7: Door Liners + Timber
C8: Lawsons | D8: 252 | E8: 1 | F8: {=D8*E8} -> 252 | G8: 252 | H8: 45971 | I8: Paid Mama | J8: Plywood
C9: Tree Clearence - Garden | D9: 320 | E9: 1 | F9: {=D9*E9} -> 320 | G9: 320 | H9: 45973 | I9: Paid Cash
C10: Electrics | D10: 4000 | E10: 1 | F10: {=D10*E10} -> 4000 | G10: 4000 | H10: 45975 | I10: Paid Cash | J10: £5,000 to pay
C11: Plumbing | D11: 1000 | E11: 1 | F11: 1000 | G11: 1000 | H11: 45976 | I11: Paid Cash | J11: £8000 to pay
C12: Lawsons - Garden £500 | D12: 655.72 | E12: 1 | F12: {=D12*E12} -> 655.72 | G12: 655.72 | H12: 45975 | I12: Paid Mama | J12: Sleepers + Timber
C13: Distribution Tiles - GARDEN | D13: 1829.16 | E13: 1 | F13: {=D13*E13} -> 1829.16 | G13: 1829.16 | H13: 45975 | I13: Paid Mama | J13: Outdoor tiles…. 130m2
C14: Alpec Windows | D14: 1000 | E14: 1 | F14: {=D14*E14} -> 1000 | G14: 1000 | H14: 45975 | I14: Paid Cash
C15: Plumbing | D15: 1000 | E15: 1 | F15: {=D15*E15} -> 1000 | G15: 1000 | H15: 45983 | I15: Paid cash | J15: £7000 to pay
C16: Pro Tiler | D16: 1164.14 | E16: 1 | F16: {=D16*E16} -> 1164.14 | G16: 1164.14 | H16: 45981 | I16: Paid AMEX - Prima + ditra + Adhesive
C17: Sam- Hedge removal + clear - Garden | D17: 200 | E17: 1 | F17: {=D17*E17} -> 200 | G17: 200 | H17: 45980 | I17: paid cash
C18: Lusso Stone | D18: 1456 | E18: 1 | F18: {=D18*E18} -> 1456 | G18: 1456 | H18: 45981 | I18: Paid dad debit card | J18: Bathroom sanitary
C19: Eurocell | D19: 650 | E19: 1 | F19: {=D19*E19} -> 650 | G19: 650 | H19: 45982 | I19: Paid cash | J19: Fascia +Gutter
C20: Lawsons | D20: 205.38 | E20: 1 | F20: {=D20*E20} -> 205.38 | G20: 205.38 | H20: 45982 | I20: paid cap on tap watton card | J20: Plaster materials
C21: Hauws Gray - Garden | D21: 500 | E21: 1 | F21: {=D21*E21} -> 500 | G21: 500 | H21: 45982 | I21: Paid cash for bullnose garden etc | J21: garden
C22: Distribution Tiles | D22: 2221.98 | E22: 1 | F22: {=D22*E22} -> 2221.98 | G22: 2221.98 | H22: 45982 | I22: Paid via shop | J22: tiles for entire floor of GF + bathrooms
C23: Rest of bathroom - Various | D23: 3100 | E23: 1 | F23: {=D23*E23} -> 3100 | G23: 3100 | H23: 45984 | I23: Paid dad debit card | J23: Bathroom sanitary
C24: Lawsons | D24: 189 | E24: 1 | F24: {=D24*E24} -> 189 | G24: 189 | H24: 45985 | I24: paid mama | J24: sheet covering
C25: George Davies Turf - Garden | D25: 586.2 | E25: 1 | F25: {=D25*E25} -> 586.2 | G25: 586.2 | H25: 45986 | I25: Paid dad debit card | J25: Turf back garden only
C26: Tool Station | D26: 31.98 | E26: 1 | F26: {=D26*E26} -> 31.98 | G26: 31.98 | H26: 45987 | I26: Cap on tap | J26: Plaster materials
C27: Build BASE - Garden | D27: 132 | E27: 1 | F27: 132 | G27: 132 | H27: 45987 | I27: Cap on tap | J27: Drain covers back garden tile
C28: Pro Tiler | D28: 1272.41 | E28: 1 | F28: {=D28*E28} -> 1272.41 | G28: 1272.41 | H28: 45987 | I28: dad debit card | J28: adhesive + self leveller for bedrooom
C29: Clearence guys | D29: 650 | E29: 1 | F29: 650 | G29: 650 | H29: 45989 | I29: Cash payment
C30: Plumbing | D30: 3000 | E30: 1 | F30: {=D30*E30} -> 3000 | G30: 3000 | H30: 45989 | I30: Cash payment | J30: plumbing £4000 to pay
C31: Eurocell | D31: 50 | E31: 1 | F31: {=D31*E31} -> 50 | G31: 50 | H31: 45989 | I31: Cap on tap | J31: Fascia +Gutter
C32: welwyn skips | D32: 426 | E32: 1 | F32: {=D32*E32} -> 426 | G32: 426 | H32: 45992 | I32: dad debit card | J32: skip
C33: Howdens | D33: 1917 | E33: 1 | F33: {=D33*E33} -> 1917 | G33: 1917 | H33: 45992 | I33: on account | J33: All doors, arch, hardware skirts
C34: Lawsons | D34: 290.84 | E34: 1 | F34: {=D34*E34} -> 290.84 | G34: 290.84 | H34: 45993 | I34: mama | J34: timber for bathroom floor cover
C35: Tops tiles | D35: 131.16 | E35: 1 | F35: {=D35*E35} -> 131.16 | G35: 131.16 | H35: 45994 | I35: Cap on tap | J35: grout etc
C36: gills plumbing | D36: 250 | E36: 1 | F36: {=D36*E36} -> 250 | G36: 250 | H36: 45996 | I36: sanj card | J36: rest of bathroom
C37: Kitchen- Cabinets Direct | D37: 2000 | E37: 1 | F37: {=D37*E37} -> 2000 | G37: 2000 | H37: 45996 | I37: Cash payment | J37: £900 to pay when drawers swap
C38: Johnstones Paint | D38: 70 | E38: 1 | F38: {=D38*E38} -> 70 | G38: 70 | H38: 45999 | I38: dad card | J38: paint for mistcoat
C39: AC Tools | D39: 70 | E39: 1 | F39: {=D39*E39} -> 70 | G39: 70 | H39: 46000 | I39: Cash payment | J39: adhesives for skirting etc
C40: George Davies Turf - Garden | D40: 424.32 | E40: 1 | F40: {=D40*E40} -> 424.32 | G40: 424.32 | H40: 46003 | I40: dad debit card | J40: Grass for garden front
...

Sheet Remaining
A1: Amount | B1: Items
A6: Mama | D6: January | E6: £3k | F6: cash to pay but all accounted and detailed under materials
